Workbook
Name JR_PAGE_ANCHOR_0_1: #REF!

Sheet Gabungan Eval + Marine
A1: KPI | B1: Penilaian | C1: Source | D1: Data Source | E1: Periode Input
A2: % Identification and Evaluation of K3L Regulations based on Regulatory Compliance System | B2: L1: <96% Pemenuhan GCI perusahaan L2: 97% Pemenuhan GCI perusahaan L3: 98% Pemenuhan GCI perusahaan L4: 99% Pemenuhan GCI perusahaan L5: 100% Pemenuhan GCI perusahaan based on Regulatory Compliance System | C2: RCS
A3: Penurunan AFR | B3: Index nilai penurunan AFR dibandingkan performa aktual tahun sebelumnya target : L1: AFR avg/month dan kategori insiden lebih tinggi dari tahun sebelumnya L2 : AFR avg/month dan kategori insiden tidak ada perubahan dibanding tahun sebelumnya L3: AFR avg/month <5% dibanding AFR avg/month tahun sebelumnya L4 : AFR avg/month <7% dibanding AFR avg/month tahun sebelumnya L5 : AFR avg/month <7% dibanding AFR avg/month tahun sebelumnya dan kategori insiden tidak meningkat dibanding tahun 2024 | C3: Data Inc | D3: https://docs.google.com/spreadsheets/d/1923a1VDN5YPZBk0tY5Lql1v6K66aKvm5RH0smB78gNs/edit?gid=0#gid=0 | E3: Weekly
A4: Penurunan Jumlah incident HIPO dan Incident Berulang | B4: Frequency Incident kategori HIPO dan Insiden berulang menurun dibandingkan performa aktual tahun sebelumnya target : L1: HIPO Incident avg/month dan kategori insiden lebih tinggi dari tahun sebelumnya L2 : HIPO Incident avg/month dan kategori insiden tidak ada perubahan dibanding tahun sebelumnya L3: HIPO Incident avg/month <5% dibanding HIPO Incident avg/month tahun sebelumnya. L4 : HIPO Incident avg/month <7% dibanding HIPO Incident avg /month tahun sebelumnya, tidak terdapat pengulangan insiden (rootcause, lokasi dan aktivitas yang sama) selama tahun berjalan. L5 : HIPO Incident avg/month <7% dibanding HIPO Incident avg/month tahun sebelumnya, kategori insiden tidak meningkat dibanding tahun 2025 (jumlah HIPO GR), tidak terdapat pengulangan insiden (rootcause, lokasi dan aktivitas yang sama) di banding periode tahun sebelumnya dan selama tahun berjalan | C4: Data Inc | D4: https://docs.google.com/spreadsheets/d/1923a1VDN5YPZBk0tY5Lql1v6K66aKvm5RH0smB78gNs/edit?gid=0#gid=0 | E4: Weekly
A5: Evaluator Function (Evaluation Coverage) | B5: Tidak terdapat penyebab kecelakaan (Rootcause/Non Confirmity) dikarenakan fungsi Evaluator yang tidak berjalan dan memastikan evaluasi program dilakukan L1 : 30% Program masuk dalam evaluasi tematik L2 : 50% Program masuk dalam evaluasi tematik L3 : 80% Program masuk dalam evaluasi tematik L4 : 90% Program masuk dalam evaluasi tematik L5 : 100% Program masuk dalam evaluasi tematik | C5: Input Manual | E5: Tahunan
A6: Monitoring Hazard Report & Inspeksi | B6: Monitoring yang dilakukan perihal jumlah laporan hazard & inspeksi dengan status closed dibandingkan dengan jumlah laporan hazard & inspeksi yang masuk setiap bulannya (All Site). L1: Closed 92% dan status Closed Overdue < 5% L2: Closed 94% dan status Closed Overdue < 4% L3: Closed 95% dan status Closed Overdue < 3% L4: Closed 97% dan status Closed Overdue < 2% L5: Closed 99% dan status Closed Overdue < 1% | C6: Kompilasi SAP | E6: Weekly
A7: Laporan Rutin Bulanan ESDM | B7: Tanggal pengumpulan laporan Bulanan ESDM L1: tanggal 12 L2: tanggal 11 L3: tanggal 10 L4: tanggal 9 L5: tanggal 8 | C7: Input Manual | E7: Bulanan
A8: Laporan RKAB ESDM | B8: Tanggal pengumpulan laporan RKAB ESDM L1: tanggal 24 L2: tanggal 23 L3: tanggal 22 L4: tanggal 21 L5: tanggal 20 | C8: Input Manual | E8: Quarterly
A9: Laporan P2K3 Triwulan | B9: Tanggal pengumpulan laporan P2K3 Triwulan L1: tanggal 12 L2: tanggal 11 L3: tanggal 10 L4: tanggal 9 L5: tanggal 8 | C9: Input Manual | E9: Quarterly
A10: # Coaching | B10: Jumlah pelaksanaan kegiatan coaching untuk mendukung safety performance. Calculation: # Jumlah coaching L1: 0 L2: 1 L3: 2 L4: 3 L5: 4 | C10: Kompilasi SAP | E10: Monthly
A11: # Observation | B11: Jumlah pelaksanaan kegiatan observasi untuk mendukung safety performance, sesuai tanggung jawab area dan berdasarkan list activity yang dibuat oleh masing-masing departemen. Calculation: # Jumlah observasi L1: 1 L2: 2 L3: 3 L4: 4 L5: 5 | C11: Kompilasi SAP | E11: Monthly
A12: # Inspection | B12: Jumlah pelaksanaan kegiatan inspeksi untuk mendukung safety performance, sesuai tanggung jawab area dan berdasarkan list activity yang dibuat oleh masing-masing departemen. Calculation: # Jumlah inspeksi L1: 1 L2: 2 L3: 3 L4: 4 L5: 5 | C12: Kompilasi SAP | E12: Monthly
A13: # Hazard Report | B13: Jumlah pelaksanaan kegiatan hazard report untuk mendukung safety performance. Calculation: # Jumlah Hazard Report L1: 0 L2: 1 L3: 2 L4: 3 L5: 4 | C13: Kompilasi SAP | E13: Monthly
A14: Pengiriman weekly safety report (Safety alignment & ISC) | B14: Index ketepatan waktu pengiriman dan kualitas report weekly (untuk keperluan meeting safety alignment & ISC). L1: Dikirimkan setelah pukul 00:00 setiap hari Selasa L2: Dikirimkan di hari selasa sebelum pukul 23:59 L3: Dikirimkan setiap hari Senin sebelum pukul 22:00 L4: Dikirimkan setiap hari Senin sebelum pukul 21:00 L5: Dikirimkan setiap hari Senin sebelum pukul 21:00 dan tidak ada revisi di hari H pelaksanaan meeting | C14: Input Manual | E14: Weekly
A15: Evaluasi Analisa Safety (monthly report) | B15: Laporan Safety Performance disampaikan dalam forum HSECM, IT & Safety Alignment, serta ISC L1: Tanggal 9 L2: Tanggal 8 L3: Tanggal 7 L4: Tanggal 6 L5: Tanggal 5 | C15: Input Manual | E15: Monthly
A16: Kontrol Pemenuhan Rekomendasi LPI | B16: Pemenuhan rekomendasi dari hasil investigasi (Berdasarkan list rekomendasi yang dikeluarkan dari tim OHS) L1: 90% dan terdapat RTP Check Incident Injury (First Aid up) dalam 2 tahun terakhir L2: 92% dan terdapat RTP Check Incident Injury (First Aid up) dalam 2 tahun terakhir L3: 94% dan terdapat RTP Check Incident Injury (First Aid up) dalam 2 tahun terakhir L4: 97% dan terdapat RTP Check Incident Injury (First Aid up) dalam 2 tahun terakhir L5: 99% dan terdapat RTP Check Incident Injury (First Aid up) dalam 2 tahun terakhir | C16: BeInvestigasi | E16: Semester
... A20: Evaluasi Analisa Safety (Monthly Report) | B20: Laporan Safety Monthly site L1: Tanggal 9 L2: Tanggal 8 L3: Tanggal 7 L4: Tanggal 6 (Zero Program Scorecard Menurun dalam 2 periode kebelakang dari bulan Report Evaluasi secara repetitive) L5: Tanggal 5 (Zero Gap pada related causal Layer 2.4 dan 2.13) | C20: Input Manual | E20: Monthly
A21: Ratio LTISR | B21: Index nilai penurunan LTISR berdasarkan range berdasarkan Permen 1827: target : L1: 6.000 ( Fatality) L2 : 84 hari (4 minor) L3: 63 hari (3 minor ) L4 : 42 hari (2 minor) L5 : 0 | C21: Data Inc | D21: https://docs.google.com/spreadsheets/d/1923a1VDN5YPZBk0tY5Lql1v6K66aKvm5RH0smB78gNs/edit?gid=0#gid=0 | E21: Tahunan
A22: Follow up temuan ESDM | B22: L5: 100% L4: 98% L3: 96% L2: 93% L1: 90% | C22: Input Manual | E22: Semester
A23: LTISR | B23: Loss Time Injury Severity Rate khusus area Marine PT. BC : rata-rata keparahan tingkat cedera yang mengakibatkan hilangnya waktu kerja L1: 4 kejadian LTI L2: 3 kejadian LTI L3: 2 kejadian LTI L4: 1 kejadian LTI L5: tidak ada kejadian LTI | C23: Data Inc | D23: https://docs.google.com/spreadsheets/d/1923a1VDN5YPZBk0tY5Lql1v6K66aKvm5RH0smB78gNs/edit?gid=0#gid=0 | E23: Tahunan
A24: Pemenuhan Hazard Report (Closed) - Marine Operasional | B24: Monitoring yang dilakukan perihal jumlah laporan hazard & inspeksi dengan status closed dibandingkan dengan jumlah laporan hazard & inspeksi yang masuk setiap bulannya (All Site). L1: Closed 92% dan status Closed Overdue < 5% L2: Closed 94% dan status Closed Overdue < 4% L3: Closed 95% dan status Closed Overdue < 3% L4: Closed 97% dan status Closed Overdue < 2% L5: Closed 99% dan status Closed Overdue < 1% | C24: Kompilasi SAP | E24: Monthly
A25: Jumlah Accident Marine | B25: Jumlah Accident di area Marine Operasional dengan mempertimbangkan kenaikan jumlah shipment, penambahan jetty baru untuk barging dan kelayakan/umur armada di area Operasional - L1: 8 kejadian - L2: 7 kejadian - L3: 6 kejadian - L4: 5 kejadian - L5: 4 kejadian | C25: Data Inc | D25: https://docs.google.com/spreadsheets/d/1923a1VDN5YPZBk0tY5Lql1v6K66aKvm5RH0smB78gNs/edit?gid=0#gid=0 | E25: Semester
A26: HIRA | B26: Melakukan review HIRA di Mitra Kerja Marine (Khusus Area Marine) L1: 90% L2: 92% L3: 94% L4: 96% L5: 98% | C26: Input Manual | E26: Tahunan
A27: % Fulfillment Incident investigation - Area Marine | B27: Pemenuhan rekomendasi dari hasil investigasi (Khusus Area Marine) L1: 90% dan terdapat RTP Check Incident Injury (First Aid up) dalam 2 tahun terakhir L2: 92% dan terdapat RTP Check Incident Injury (First Aid up) dalam 2 tahun terakhir L3: 94% dan terdapat RTP Check Incident Injury (First Aid up) dalam 2 tahun terakhir L4: 97% dan terdapat RTP Check Incident Injury (First Aid up) dalam 2 tahun terakhir L5: 99% dan terdapat RTP Check Incident Injury (First Aid up) dalam 2 tahun terakhir | C27: BeInvestigasi | E27: Semester
A28: Peningkatan TBC | B28: Pelaporan TBC untuk mitra kerja Marine mencapai target yang di tentukan di semester ke I L1: Index 1 = Laporan TBC khusus untuk area Marine rata - rata 80 temuan per minggu L2: Index 2 = Laporan TBC khusus untuk area Marine rata - rata 85 temuan per minggu L3: Index 3 = Laporan TBC khusus untuk area Marine rata - rata 90 temuan per minggu L4: Index 4 = Laporan TBC khusus untuk area Marine rata - rata 95 temuan per minggu L5: Index 5 = Laporan TBC khusus untuk area Marine rata - rata 100 temuan per minggu Pelaporan TBC untuk mitra kerja Marine mencapai target yang di tentukan di semester ke II L1: Index 1 = Laporan TBC khusus untuk area Marine rata - rata 105 temuan per minggu L2: Index 2 = Laporan TBC khusus untuk area Marine rata - rata 110 temuan per minggu L3: Index 3 =Laporan TBC khusus untuk area Marine rata - rata 115 temuan per minggu L4: Index 4 = Laporan TBC khusus untuk area Marine rata - rata 120 temuan per minggu L5: Index 5 = Laporan TBC khusus untuk area Marine rata - rata 125 temuan per minggu | C28: Kompilasi SAP | E28: Semester
A29: Innovation Safety Marine Innovation Project Completion | B29: Penyelesaian scope project dari project marine safety, project based : L1: Completion : 80%, Improvement Generated : ≥1 improvement, Impact : Perbaikan minor pada reporting / dashboard L2: Completion : 85%, Improvement Generated : ≥1 improvement, Impact : Mempercepat proses monitoring atau reporting L3: Completion : 90%, Improvement Generated : ≥2 improvement, Impact : Mengurangi manual work / meningkatkan efisiensi proses L4: Completion : 100% dan Presented & Approved GM OHS, Improvement Generated : ≥3 improvement, Impact : Lintas fungsi (OHS / Operation) dan meningkatkan decision making L5: Completion : 100% dan Presented ke KTT, Improvement Generated : ≥4 improvement, Impact : Lintas Divisi,Transformasi proses kerja / automation signifikan yang berdampak ke performance monitoring perusahaan | C29: Input Manual | E29: Semester

Sheet Updated KPI
A1: Owner | B1: KPI | D1: After
A2: Supt SEDCR, Safety Eval, DCRS | B2: Monitoring Hazard Report & Inspeksi | C2: Monitoring yang dilakukan perihal jumlah laporan hazard & inspeksi dengan status closed (selain closed overdue) dibandingkan dengan jumlah laporan hazard & inspeksi yang masuk setiap bulannya (All Site). L1: 92% L2: 94% L3: 95% L4: 97% L5: 99% | D2: Monitoring yang dilakukan perihal jumlah laporan hazard & inspeksi dengan status closed dibandingkan dengan jumlah laporan hazard & inspeksi yang masuk setiap bulannya (All Site). L1: Closed 92% dan status Closed Overdue < 5% L2: Closed 94% dan status Closed Overdue < 4% L3: Closed 95% dan status Closed Overdue < 3% L4: Closed 97% dan status Closed Overdue < 2% L5: Closed 99% dan status Closed Overdue < 1%
A3: Supt SEDCR, Safety Eval, DCRS | B3: Kontrol Pemenuhan Rekomendasi LPI | C3: Pemenuhan rekomendasi dari hasil investigasi (Berdasarkan list rekomendasi yang dikeluarkan dari tim OHS) L1: 90% L2: 92% L3: 94% L4: 97% L5: 99% | D3: Pemenuhan rekomendasi dari hasil investigasi (Berdasarkan list rekomendasi yang dikeluarkan dari tim OHS) L1: 90% dan terdapat RTP Check Incident Injury (First Aid up) dalam 2 tahun terakhir L2: 92% dan terdapat RTP Check Incident Injury (First Aid up) dalam 2 tahun terakhir L3: 94% dan terdapat RTP Check Incident Injury (First Aid up) dalam 2 tahun terakhir L4: 97% dan terdapat RTP Check Incident Injury (First Aid up) dalam 2 tahun terakhir L5: 99% dan terdapat RTP Check Incident Injury (First Aid up) dalam 2 tahun terakhir
A4: Supt SEDCR, Safety Eval, DCRS | B4: Safety Evaluation Innovation Project Completion | C4: Penyelesaian scope project dari project safety dashboard integration & automation secara on-time, atau pengerjaan unplanned project/tasks, project based L1: 80% L2: 85% L3: 90% L4: 95% L5: 100% | D4: Penyelesaian scope project dari project safety dashboard integration & automation secara on-time, atau pengerjaan unplanned project/tasks, project based L1: Completion : 80%, Improvement Generated : ≥1 improvement, Impact : Perbaikan minor pada reporting / dashboard L2: Completion : 85%, Improvement Generated : ≥2 improvement, Impact : Mempercepat proses monitoring atau reporting L3: Completion : 90%, Improvement Generated : ≥3 improvement, Impact : Mengurangi manual work / meningkatkan efisiensi proses L4: Completion : 100% dan Presented & Approved GM OHS, Improvement Generated : ≥4 improvement, Impact : Lintas fungsi (OHS / Operation) dan meningkatkan decision making L5: Completion : 100% dan Presented ke KTT, Improvement Generated : ≥5 improvement, Impact : Lintas Divisi Transformasi proses kerja / automation signifikan yang berdampak ke performance monitoring perusahaan
A5: Safety Eval | B5: # Inspection | C5: Jumlah pelaksanaan kegiatan inspeksi untuk mendukung safety performance, sesuai tanggung jawab area dan berdasarkan list activity yang dibuat oleh masing-masing departemen. Calculation: # Jumlah inspeksi L1: 2 L2: 3 L3: 4 L4: 5 L5: 6 | D5: Jumlah pelaksanaan kegiatan inspeksi untuk mendukung safety performance, sesuai tanggung jawab area dan berdasarkan list activity yang dibuat oleh masing-masing departemen. Calculation: # Jumlah inspeksi L1: 2 & <50% TBC L2: 3 & 60% TBC L3: 4 & 70% TBC L4: 5 & 80% TBC L5: 6 & 90% TBC
A6: Safety Eval | B6: # Hazard Report | C6: Jumlah pelaksanaan kegiatan hazard report untuk mendukung safety performance. Calculation: # Jumlah Hazard Report L1: 1 L2: 2 L3: 3 L4: 4 L5: 5 | D6: Jumlah pelaksanaan kegiatan hazard report untuk mendukung safety performance. Calculation: # Jumlah Hazard Report L1: 1 & <50% TBC L2: 2 & 60% TBC L3: 3 & 70% TBC L4: 4 & 80% TBC L5: 5 & 90% TBC
A7: Safety Eval | B7: Pengiriman Feed material untuk meeting alignment & ISC | C7: Pembuatan dan Pengiriman feed material meeting alignment & ISC setiap hari Jumat. L1: Hari Senin sebelum Pukul 12:00 L2: Hari Senin sebelum Pukul 10:00 L3: Hari Jumat sebelum Pukul 14:00 L4: Hari Jumat sebelum Pukul 12:00 L5: Hari Jumat sebelum Pukul 10:00 | D7: Pembuatan dan Pengiriman feed material meeting alignment & ISC setiap hari Jumat. L1: Hari Senin sebelum Pukul 12:00 dan Zero Thematic Issue L2: Hari Senin sebelum Pukul 10:00 dan Zero Thematic Issue L3: Hari Jumat sebelum Pukul 14:00 dan Zero Thematic Issue L4: Hari Jumat sebelum Pukul 12:00 dan Lead 1 Thematic Issue L5: Hari Jumat sebelum Pukul 10:00 dan Lead 2 Thematic Issue
A8: Safety Eval | B8: Evaluasi Analisa Safety (Monthly Report) | C8: Laporan Safety Monthly site L1: Tanggal 9 L2: Tanggal 8 L3: Tanggal 7 L4: Tanggal 6 L5: Tanggal 5 | D8: Laporan Safety Monthly site L1: Tanggal 9 L2: Tanggal 8 L3: Tanggal 7 L4: Tanggal 6 (Zero Program Scorecard Menurun dalam 2 periode kebelakang dari bulan Report Evaluasi secara repetitive) L5: Tanggal 5 (Zero Gap pada related causal Layer 2.4 dan 2.13)
A9: Supt SEDCR, Safety Eval, DCRS | B9: Penurunan Jumlah incident HIPO dan Incident Berulang | C9: Frequency Incident kategori HIPO menurun dibandingkan performa aktual tahun sebelumnya target : L1: HIPO Incident avg/month dan kategori insiden lebih tinggi dari tahun sebelumnya L2 : HIPO Incident avg/month dan kategori insiden tidak ada perubahan dibanding tahun sebelumnya L3: HIPO Incident avg/month <5% dibanding HIPO Incident avg/month tahun sebelumnya L4 : HIPO Incident avg/month <7% dibanding HIPO Incident avg /month tahun sebelumnya L5 : HIPO Incident avg/month <7% dibanding HIPO Incident avg/month tahun sebelumnya dan kategori insiden tidak meningkat dibanding tahun 2024 (jumlah HIPO GR) | D9: Frequency Incident kategori HIPO dan Insiden berulang menurun dibandingkan performa aktual tahun sebelumnya target : L1: HIPO Incident avg/month dan kategori insiden lebih tinggi dari tahun sebelumnya L2 : HIPO Incident avg/month dan kategori insiden tidak ada perubahan dibanding tahun sebelumnya L3: HIPO Incident avg/month <5% dibanding HIPO Incident avg/month tahun sebelumnya. L4 : HIPO Incident avg/month <7% dibanding HIPO Incident avg /month tahun sebelumnya, tidak terdapat pengulangan insiden (rootcause, lokasi dan aktivitas yang sama) selama tahun berjalan. L5 : HIPO Incident avg/month <7% dibanding HIPO Incident avg/month tahun sebelumnya, kategori insiden tidak meningkat dibanding tahun 2025 (jumlah HIPO GR), tidak terdapat pengulangan insiden (rootcause, lokasi dan aktivitas yang sama) di banding periode tahun sebelumnya dan selama tahun berjalan
A10: Safety Eval, DCRS | B10: Pengiriman Safety Site Weekly Report | C10: Pembuatan dan Pengiriman evaluasi Mingguan (Safety Performance, Evaluasi Hazard khususnya Hazard High Risk, Monitoring Pengawasan Area/Aktvitas Kritis, Evaluasi Pelaksanaan SIB, PJA Performance dan Tren Pelaporan Hazard High Risk, Observasi Area/Aktivitas Kritis, Evaluasi Hazard Covid serta rekomendasi hasil Evaluasi). L1: Hari Senin diatas pukul 17:00 L2: Hari Senin sebelum pukul 16:00 L3: Hari Senin sebelum Pukul 14:00 L4: Hari Senin sebelum Pukul 12:00 namun masih ada revisi L5: Hari Senin sebelum Pukul 12:00 dan tidak ada revisi lanjutan | D10: Pembuatan, Pengiriman evaluasi Mingguan dan efektifitas rekomendasi (Safety Performance, Evaluasi Hazard khususnya Hazard High Risk, Monitoring Pengawasan Area/Aktvitas Kritis, Evaluasi Pelaksanaan SIB, PJA Performance dan Tren Pelaporan Hazard High Risk, Observasi Area/Aktivitas Kritis, Evaluasi Hazard Covid serta rekomendasi hasil Evaluasi). L1: Hari Senin diatas pukul 17:00 dan <40% rekomendasi evaluator diimplementasikan L2: Hari Senin sebelum pukul 16:00 dan 40–54% rekomendasi evaluator diimplementasikan L3: Hari Senin sebelum Pukul 14:00 dan 55–64% rekomendasi evaluator diimplementasikan L4: Hari Senin sebelum Pukul 12:00 dan 65–74% rekomendasi evaluator diimplementasikan L5: Hari Senin sebelum Pukul 12:00 dan ≥75% rekomendasi evaluator diimplementasikan
A12: Marine Supt | B12: Kontrol Pemenuhan Rekomendasi LPI | C12: Pemenuhan rekomendasi dari hasil investigasi (Khusus Area Marine) L1: 90% L2: 92% L3: 94% L4: 97% L5: 99% | D12: Pemenuhan rekomendasi dari hasil investigasi (Berdasarkan list rekomendasi yang dikeluarkan dari tim OHS) L1: 90% dan terdapat RTP Check Incident Injury (First Aid up) dalam 2 tahun terakhir L2: 92% dan terdapat RTP Check Incident Injury (First Aid up) dalam 2 tahun terakhir L3: 94% dan terdapat RTP Check Incident Injury (First Aid up) dalam 2 tahun terakhir L4: 97% dan terdapat RTP Check Incident Injury (First Aid up) dalam 2 tahun terakhir L5: 99% dan terdapat RTP Check Incident Injury (First Aid up) dalam 2 tahun terakhir
A13: Marine Supt | B13: Monitoring Hazard Report & Inspeksi | C13: Monitoring yang dilakukan perihal jumlah laporan hazard & inspeksi dengan status closed (selain closed overdue) dibandingkan dengan jumlah laporan hazard & inspeksi yang masuk setiap bulannya (Marine). L1: 92% L2: 94% L3: 95% L4: 97% L5: 99% | D13: Monitoring yang dilakukan perihal jumlah laporan hazard & inspeksi dengan status closed dibandingkan dengan jumlah laporan hazard & inspeksi yang masuk setiap bulannya (Marine). L1: Closed 92% dan status Closed Overdue < 5% L2: Closed 94% dan status Closed Overdue < 4% L3: Closed 95% dan status Closed Overdue < 3% L4: Closed 97% dan status Closed Overdue < 2% L5: Closed 99% dan status Closed Overdue < 1%
A14: Marine Supv | B14: Kontrol Pemenuhan Rekomendasi LPI | C14: Pemenuhan rekomendasi dari hasil investigasi (Khusus Area Marine) L1: 90% L2: 92% L3: 94% L4: 97% L5: 99% | D14: Pemenuhan rekomendasi dari hasil investigasi (Berdasarkan list rekomendasi yang dikeluarkan dari tim OHS) L1: 90% dan terdapat RTP Check Incident Injury (First Aid up) dalam 2 tahun terakhir L2: 92% dan terdapat RTP Check Incident Injury (First Aid up) dalam 2 tahun terakhir L3: 94% dan terdapat RTP Check Incident Injury (First Aid up) dalam 2 tahun terakhir L4: 97% dan terdapat RTP Check Incident Injury (First Aid up) dalam 2 tahun terakhir L5: 99% dan terdapat RTP Check Incident Injury (First Aid up) dalam 2 tahun terakhir
... A17: Marine Supv | B17: # Hazard Report | C17: Jumlah pelaksanaan kegiatan hazard report untuk mendukung safety performance. Calculation: # Jumlah Hazard Report L1: 1 L2: 2 L3: 3 L4: 4 L5: 5 | D17: Jumlah pelaksanaan kegiatan hazard report untuk mendukung safety performance. Calculation: # Jumlah Hazard Report L1: 1 & <50% TBC L2: 2 & 60% TBC L3: 3 & 70% TBC L4: 4 & 80% TBC L5: 5 & 90% TBC
A18: Marine Supt | B18: Innovation Safety Marine Innovation Project Completion | D18: Penyelesaian scope project dari project marine safety, project based : L1: Completion : 80%, Improvement Generated : ≥1 improvement, Impact : Perbaikan minor pada reporting / dashboard L2: Completion : 85%, Improvement Generated : ≥1 improvement, Impact : Mempercepat proses monitoring atau reporting L3: Completion : 90%, Improvement Generated : ≥2 improvement, Impact : Mengurangi manual work / meningkatkan efisiensi proses L4: Completion : 100% dan Presented & Approved GM OHS, Improvement Generated : ≥3 improvement, Impact : Lintas fungsi (OHS / Operation) dan meningkatkan decision making L5: Completion : 100% dan Presented ke KTT, Improvement Generated : ≥4 improvement, Impact : Lintas Divisi,Transformasi proses kerja / automation signifikan yang berdampak ke performance monitoring perusahaan
A19: Marine Supt | B19: Penurunan Jumlah incident HIPO dan Incident Berulang | C19: Frequency Incident kategori HIPO menurun dibandingkan performa aktual tahun sebelumnya (Marine) target : L1: HIPO Incident avg/month dan kategori insiden lebih tinggi dari tahun sebelumnya L2 : HIPO Incident avg/month dan kategori insiden tidak ada perubahan dibanding tahun sebelumnya L3: HIPO Incident avg/month <5% dibanding HIPO Incident avg/month tahun sebelumnya L4 : HIPO Incident avg/month <7% dibanding HIPO Incident avg /month tahun sebelumnya L5 : HIPO Incident avg/month <7% dibanding HIPO Incident avg/month tahun sebelumnya dan kategori insiden tidak meningkat dibanding tahun 2024 (jumlah HIPO GR) | D19: Frequency Incident kategori HIPO dan Insiden berulang menurun dibandingkan performa aktual tahun sebelumnya (Marine) target : L1: HIPO Incident avg/month dan kategori insiden lebih tinggi dari tahun sebelumnya L2 : HIPO Incident avg/month dan kategori insiden tidak ada perubahan dibanding tahun sebelumnya L3: HIPO Incident avg/month <5% dibanding HIPO Incident avg/month tahun sebelumnya. L4 : HIPO Incident avg/month <7% dibanding HIPO Incident avg /month tahun sebelumnya, tidak terdapat pengulangan insiden (rootcause, lokasi dan aktivitas yang sama) selama tahun berjalan. L5 : HIPO Incident avg/month <7% dibanding HIPO Incident avg/month tahun sebelumnya, kategori insiden tidak meningkat dibanding tahun 2025 (jumlah HIPO GR), tidak terdapat pengulangan insiden (rootcause, lokasi dan aktivitas yang sama) di banding periode tahun sebelumnya dan selama tahun berjalan

Sheet Supt SEDCR
A1: Perspective | B1: Objective | C1: Grup KPI | D1: KPI | E1: Deskripsi | F1: Weightage Bobot | G1: Bobot 100% | H1: % Child | I1: Detail Bobot | K1: Review Frequency | L1: Calculation | M1: UOM | N1: L1 | O1: L2 | P1: L3 | Q1: L4 | R1: L5 | S1: Keterangan | U1: Keterangan
C2: Company KPI | D2: # Safety Performance | E2: Safety Performance dihitung berdasarkan LTIFR (Dikategorikan kecelakaan tambang berdasarkan Kepmen Nomor 1827 K/30/MEM/2018) dengan target LTIFR 0.05 (setara 3 kejadian LTI, Plan MH 2023 = 57.163.613,39). Jika terjadi fatality score akan menjadi default 1. L1 = 0.09 (5 kejadian LTI)/ada kejadian fatality L2 = 0.07 (4 kejadian LTI) L3 = 0.05 (3 kejadian LTI) L4 = 0.03 (2 kejadian LTI) L5 = 0 (0 kejadian LTI)
A3: Customer | B3: Identifikasi seluruh peraturan K3L terkait di organisasi | D3: % Identification and Evaluation of K3L Regulations based on Regulatory Compliance System | E3: L1: <96% Pemenuhan GCI perusahaan L2: 97% Pemenuhan GCI perusahaan L3: 98% Pemenuhan GCI perusahaan L4: 99% Pemenuhan GCI perusahaan L5: 100% Pemenuhan GCI perusahaan based on Regulatory Compliance System | F3: 3 | G3: 5 | K3: Halfyearly | L3: Constant | M3: index | N3: 1 | O3: 2 | P3: 3 | Q3: 4 | R3: 5 | S3: Support | U3: Menggunakan yg mana | V3: S2 L1: 98% Pemenuhan GCI perusahaan L2: 99% Pemenuhan GCI perusahaan L3: 100% Pemenuhan GCI perusahaan L4: 100% Pemenuhan GCI perusahaan + Aditama GMP aspek Keselamatan L5: 100% Pemenuhan GCI perusahaan + Aditama GMP aspek Keselamatan dan trophy untuk salah satu aspek GMP di Berau Coal | Z3: 3 | AA3: 5
A4: Internal Business Process | B4: Strengthen OHS Management | D4: Penurunan AFR | E4: Index nilai penurunan AFR dibandingkan performa aktual tahun sebelumnya target : L1: AFR avg/month dan kategori insiden lebih tinggi dari tahun sebelumnya L2 : AFR avg/month dan kategori insiden tidak ada perubahan dibanding tahun sebelumnya L3: AFR avg/month <5% dibanding AFR avg/month tahun sebelumnya L4 : AFR avg/month <7% dibanding AFR avg/month tahun sebelumnya L5 : AFR avg/month <7% dibanding AFR avg/month tahun sebelumnya dan kategori insiden tidak meningkat dibanding tahun 2024 | F4: 5 | G4: 7 | H4: =F4/47 -> 0.10638298 | K4: Half Yearly | L4: Constant | M4: Index | N4: 1 | O4: 2 | P4: 3 | Q4: 4 | R4: 5 | S4: Support | U4: Penambahan point AFR ke KPI req GM | V4: *mohon ini dimasukan align dengan KPI SOD (di SOD mengacu ke ceiling main cont saja) sedang evaluator sudah sedari dulu KPI menggunakan AFR All mitra -> site per all mitra site -> mengakomodir core dan support) | Z4: 5 | AA4: 7
D5: Penurunan Jumlah incident HIPO dan Incident Berulang | E5: Frequency Incident kategori HIPO dan Insiden berulang menurun dibandingkan performa aktual tahun sebelumnya target : L1: HIPO Incident avg/month dan kategori insiden lebih tinggi dari tahun sebelumnya L2 : HIPO Incident avg/month dan kategori insiden tidak ada perubahan dibanding tahun sebelumnya L3: HIPO Incident avg/month <5% dibanding HIPO Incident avg/month tahun sebelumnya. L4 : HIPO Incident avg/month <7% dibanding HIPO Incident avg /month tahun sebelumnya, tidak terdapat pengulangan insiden (rootcause, lokasi dan aktivitas yang sama) selama tahun berjalan. L5 : HIPO Incident avg/month <7% dibanding HIPO Incident avg/month tahun sebelumnya, kategori insiden tidak meningkat dibanding tahun 2025 (jumlah HIPO GR), tidak terdapat pengulangan insiden (rootcause, lokasi dan aktivitas yang sama) di banding periode tahun sebelumnya dan selama tahun berjalan | F5: 5 | G5: 7 | H5: =F5/47 -> 0.10638298 | K5: Half Yearly | L5: Constant | M5: Index | N5: 1 | O5: 2 | P5: 3 | Q5: 4 | R5: 5 | S5: Support | U5: Request Penambahan Point KPI by GM OHS | Z5: 5 | AA5: 7
D6: Evaluator Function (Evaluation Coverage) | E6: Tidak terdapat penyebab kecelakaan (Rootcause/Non Confirmity) dikarenakan fungsi Evaluator yang tidak berjalan dan memastikan evaluasi program dilakukan L1 : 30% Program masuk dalam evaluasi tematik L2 : 50% Program masuk dalam evaluasi tematik L3 : 80% Program masuk dalam evaluasi tematik L4 : 90% Program masuk dalam evaluasi tematik L5 : 100% Program masuk dalam evaluasi tematik | F6: 5 | G6: 7 | H6: =F6/47 -> 0.10638298 | K6: Annual | L6: Constant | M6: Index | N6: 1 | O6: 2 | P6: 3 | Q6: 4 | R6: 5 | S6: Support | U6: Penambahan Coverage Evaluasi | Z6: 5 | AA6: 7
D7: Monitoring Hazard Report & Inspeksi | E7: Monitoring yang dilakukan perihal jumlah laporan hazard & inspeksi dengan status closed dibandingkan dengan jumlah laporan hazard & inspeksi yang masuk setiap bulannya (All Site). L1: Closed 92% dan status Closed Overdue < 5% L2: Closed 94% dan status Closed Overdue < 4% L3: Closed 95% dan status Closed Overdue < 3% L4: Closed 97% dan status Closed Overdue < 2% L5: Closed 99% dan status Closed Overdue < 1% | F7: 4 | G7: 6 | H7: =F7/47 -> 0.085106383 | K7: Monthly | L7: Constant | M7: Index | N7: 1 | O7: 2 | P7: 3 | Q7: 4 | R7: 5 | S7: Support | V7: Monitoring yang dilakukan perihal jumlah laporan hazard & inspeksi dengan status closed (selain closed overdue) dibandingkan dengan jumlah laporan hazard & inspeksi yang masuk setiap bulannya (All Site). L1: 90% L2: 92% L3: 94% L4: 96% L5: 98% | Z7: 4 | AA7: 6
D8: Laporan Rutin Bulanan ESDM | E8: Tanggal pengumpulan laporan Bulanan ESDM L1: tanggal 12 L2: tanggal 11 L3: tanggal 10 L4: tanggal 9 L5: tanggal 8 | F8: 4 | G8: 6 | H8: =F8/47 -> 0.085106383 | K8: Monthly | L8: Constant | M8: Date month | N8: 12 | O8: 11 | P8: 10 | Q8: 9 | R8: 8 | S8: Individual | Z8: 4 | AA8: 6
D9: Laporan RKAB ESDM | E9: Tanggal pengumpulan laporan RKAB ESDM L1: tanggal 24 L2: tanggal 23 L3: tanggal 22 L4: tanggal 21 L5: tanggal 20 | F9: 5 | G9: 7 | H9: =F9/47 -> 0.10638298 | K9: Quarterly | L9: Constant | M9: Date month | N9: 24 | O9: 23 | P9: 22 | Q9: 21 | R9: 20 | S9: Individual | Z9: 5 | AA9: 7
D10: Laporan P2K3 Triwulan | E10: Tanggal pengumpulan laporan P2K3 Triwulan L1: tanggal 12 L2: tanggal 11 L3: tanggal 10 L4: tanggal 9 L5: tanggal 8 | F10: 4 | G10: 6 | H10: =F10/47 -> 0.085106383 | K10: Quarterly | L10: Constant | M10: Date month | N10: 12 | O10: 11 | P10: 10 | Q10: 9 | R10: 8 | S10: Individual | Z10: 4 | AA10: 6
C11: Safety Accountability Program | D11: # Coaching | E11: Jumlah pelaksanaan kegiatan coaching untuk mendukung safety performance. Calculation: # Jumlah coaching L1: 0 L2: 1 L3: 2 L4: 3 L5: 4 | F11: 5 | G11: 7 | H11: =5/4 -> 1.25 | I11: 0.2 | J11: =I11*5 -> 1 | K11: Monthly | L11: Constant | M11: Number/month | N11: 0 | O11: 1 | P11: 2 | Q11: 3 | R11: 4 | S11: Individual | Z11: 5 | AA11: 7
D12: # Observation | E12: Jumlah pelaksanaan kegiatan observasi untuk mendukung safety performance, sesuai tanggung jawab area dan berdasarkan list activity yang dibuat oleh masing-masing departemen. Calculation: # Jumlah observasi L1: 1 L2: 2 L3: 3 L4: 4 L5: 5 | H12: =5/4 -> 1.25 | I12: 0.3 | J12: =I12*5 -> 1.5 | K12: Monthly | L12: Constant | M12: Number/month | N12: 1 | O12: 2 | P12: 3 | Q12: 4 | R12: 5 | S12: Individual
D13: # Inspection | E13: Jumlah pelaksanaan kegiatan inspeksi untuk mendukung safety performance, sesuai tanggung jawab area dan berdasarkan list activity yang dibuat oleh masing-masing departemen. Calculation: # Jumlah inspeksi L1: 1 L2: 2 L3: 3 L4: 4 L5: 5 | H13: =5/4 -> 1.25 | I13: 0.3 | J13: =I13*5 -> 1.5 | K13: Monthly | L13: Constant | M13: Number/month | N13: 1 | O13: 2 | P13: 3 | Q13: 4 | R13: 5 | S13: Individual
D14: # Hazard Report | E14: Jumlah pelaksanaan kegiatan hazard report untuk mendukung safety performance. Calculation: # Jumlah Hazard Report L1: 0 L2: 1 L3: 2 L4: 3 L5: 4 | H14: =5/4 -> 1.25 | I14: 0.2 | J14: =I14*5 -> 1 | K14: Monthly | L14: Constant | M14: Number/month | N14: 0 | O14: 1 | P14: 2 | Q14: 3 | R14: 4 | S14: Individual
D15: Pengiriman weekly safety report (Safety alignment & ISC) | E15: Index ketepatan waktu pengiriman dan kualitas report weekly (untuk keperluan meeting safety alignment & ISC). L1: Dikirimkan setelah pukul 00:00 setiap hari Selasa L2: Dikirimkan di hari selasa sebelum pukul 23:59 L3: Dikirimkan setiap hari Senin sebelum pukul 22:00 L4: Dikirimkan setiap hari Senin sebelum pukul 21:00 L5: Dikirimkan setiap hari Senin sebelum pukul 21:00 dan tidak ada revisi di hari H pelaksanaan meeting | F15: 7 | G15: =(F15/70)*100 -> 10 | H15: =F15/47 -> 0.14893617 | K15: Monthly | L15: Constant | M15: Index | N15: 1 | O15: 2 | P15: 3 | Q15: 4 | R15: 5 | S15: Individual | Z15: 7 | AA15: =(Z15/70)*100 -> 10
D16: Evaluasi Analisa Safety (monthly report) | E16: Laporan Safety Performance disampaikan dalam forum HSECM, IT & Safety Alignment, serta ISC L1: Tanggal 9 L2: Tanggal 8 L3: Tanggal 7 L4: Tanggal 6 L5: Tanggal 5 | F16: 4 | G16: 6 | H16: =F16/47 -> 0.085106383 | K16: Monthly | L16: Constant | M16: Date month | N16: 9 | O16: 8 | P16: 7 | Q16: 6 | R16: 5 | S16: Individual | Z16: 4 | AA16: 6
D17: Kontrol Pemenuhan Rekomendasi LPI | E17: Pemenuhan rekomendasi dari hasil investigasi (Berdasarkan list rekomendasi yang dikeluarkan dari tim OHS) L1: 90% dan terdapat RTP Check Incident Injury (First Aid up) dalam 2 tahun terakhir L2: 92% dan terdapat RTP Check Incident Injury (First Aid up) dalam 2 tahun terakhir L3: 94% dan terdapat RTP Check Incident Injury (First Aid up) dalam 2 tahun terakhir L4: 97% dan terdapat RTP Check Incident Injury (First Aid up) dalam 2 tahun terakhir L5: 99% dan terdapat RTP Check Incident Injury (First Aid up) dalam 2 tahun terakhir | F17: 4 | G17: 6 | H17: =F17/47 -> 0.085106383 | K17: Halfyearly | L17: Constant | M17: Index | N17: 1 | O17: 2 | P17: 3 | Q17: 4 | R17: 5 | S17: Individual | V17: Pemenuhan rekomendasi dari hasil investigasi (Berdasarkan list rekomendasi yang dikeluarkan dari tim OHS) L1: 87% L2: 90% L3: 93% L4: 96% L5: 99% | Z17: 4 | AA17: 6
C18: Innovation | D18: Safety Evaluation Innovation Project Completion | E18: Penyelesaian scope project dari project safety dashboard integration & automation secara on-time, atau pengerjaan unplanned project/tasks, project based L1: Completion : 80%, Improvement Generated : ≥1 improvement, Impact : Perbaikan minor pada reporting / dashboard L2: Completion : 85%, Improvement Generated : ≥2 improvement, Impact : Mempercepat proses monitoring atau reporting L3: Completion : 90%, Improvement Generated : ≥3 improvement, Impact : Mengurangi manual work / meningkatkan efisiensi proses L4: Completion : 100% dan Presented & Approved GM OHS, Improvement Generated : ≥4 improvement, Impact : Lintas fungsi (OHS / Operation) dan meningkatkan decision making L5: Completion : 100% dan Presented ke KTT, Improvement Generated : ≥5 improvement, Impact : Lintas Divisi Transformasi proses kerja / automation signifikan yang berdampak ke performance monitoring perusahaan | F18: 15 | G18: 20 | K18: Halfyearly | L18: Constant | M18: Index | N18: 1 | O18: 2 | P18: 3 | Q18: 4 | R18: 5 | S18: Individual | Z18: 15 | AA18: 20
B19: TOTAL | D19: =COUNTA(D3:D17) -> 15 | F19: =SUM(F3:F17,F18:F18) -> 70 | G19: =SUM(G3:G17,G18:G18) -> 100 | Z19: =SUM(Z3:Z17,Z18:Z18) -> 70

Sheet Safety Evaluator
A1: Perspective | B1: Objective | C1: KPI | D1: Deskripsi | E1: Review Frequency | F1: Weightage Bobot | G1: Bobot 100% | H1: Detail Bobot | I1: Calculation | J1: UOM | K1: L1 | L1: L2 | M1: L3 | N1: L4 | O1: L5 | P1: Keterangan
A2: Internal Business Process | B2: Strengthen OHS Management | C2: AFR level site | D2: Index nilai penurunan AFR dibandingkan performa aktual tahun sebelumnya target : L1: AFR avg/month dan kategori insiden lebih tinggi dari tahun sebelumnya L2 : AFR avg/month dan kategori insiden tidak ada perubahan dibanding tahun sebelumnya L3: AFR avg/month <5% dibanding AFR avg/month tahun sebelumnya L4 : AFR avg/month <7% dibanding AFR avg/month tahun sebelumnya L5 : AFR avg/month <7% dibanding AFR avg/month tahun sebelumnya dan kategori insiden tidak meningkat dibanding tahun 2024 | E2: Half Yearly | F2: 3 | G2: 4 | I2: Constant | J2: Index | K2: 1 | L2: 2 | M2: 3 | N2: 4 | O2: 5 | P2: Support
C3: Penurunan Jumlah incident HIPO dan Incident Berulang | D3: Frequency Incident kategori HIPO dan Insiden berulang menurun dibandingkan performa aktual tahun sebelumnya target : L1: HIPO Incident avg/month dan kategori insiden lebih tinggi dari tahun sebelumnya L2 : HIPO Incident avg/month dan kategori insiden tidak ada perubahan dibanding tahun sebelumnya L3: HIPO Incident avg/month <5% dibanding HIPO Incident avg/month tahun sebelumnya. L4 : HIPO Incident avg/month <7% dibanding HIPO Incident avg /month tahun sebelumnya, tidak terdapat pengulangan insiden (rootcause, lokasi dan aktivitas yang sama) selama tahun berjalan. L5 : HIPO Incident avg/month <7% dibanding HIPO Incident avg/month tahun sebelumnya, kategori insiden tidak meningkat dibanding tahun 2025 (jumlah HIPO GR), tidak terdapat pengulangan insiden (rootcause, lokasi dan aktivitas yang sama) di banding periode tahun sebelumnya dan selama tahun berjalan | E3: Half Yearly | F3: 3 | G3: 4 | I3: Constant | J3: Index | K3: 1 | L3: 2 | M3: 3 | N3: 4 | O3: 5 | P3: Support | R3: Request Penambahan Point KPI by SM OHS
C4: ='Supt SEDCR'!D6 -> Evaluator Function (Evaluation Coverage) | D4: ='Supt SEDCR'!E6 -> Tidak terdapat penyebab kecelakaan (Rootcause/Non Confirmity) dikarenakan fungsi Evaluator yang tidak berjalan dan memastikan evaluasi program dilakukan L1 : 30% Program masuk dalam evaluasi tematik L2 : 50% Program masuk dalam evaluasi tematik L3 : 80% Program masuk dalam evaluasi tematik L4 : 90% Program masuk dalam evaluasi tematik L5 : 100% Program masuk dalam evaluasi tematik | E4: ='Supt SEDCR'!K6 -> Annual | F4: ='Supt SEDCR'!F6 -> 5 | G4: 8 | I4: ='Supt SEDCR'!L6 -> Constant | J4: Index | K4: ='Supt SEDCR'!N6 -> 1 | L4: ='Supt SEDCR'!O6 -> 2 | M4: ='Supt SEDCR'!P6 -> 3 | N4: ='Supt SEDCR'!Q6 -> 4 | O4: ='Supt SEDCR'!R6 -> 5 | P4: ='Supt SEDCR'!S6 -> Support | R4: ='Supt SEDCR'!U6 -> Penambahan Coverage Evaluasi
C5: # Coaching | D5: Jumlah pelaksanaan kegiatan coaching report untuk mendukung safety performance. Calculation: # Jumlah coaching L1: 1 L2: 2 L3: 3 L4: 4 L5: 5 | E5: Monthly | F5: 10 | G5: 12 | H5: 15 | I5: Constant | J5: NOS/month | K5: 1 | L5: 2 | M5: 3 | N5: 4 | O5: 5 | P5: Individual
C6: # Observation | D6: Jumlah pelaksanaan kegiatan observasi untuk mendukung safety performance, sesuai tanggung jawab area dan berdasarkan list activity yang dibuat oleh masing-masing departemen. Calculation: # Jumlah observasi L1: 2 L2: 3 L3: 4 L4: 5 L5: 6 | E6: Monthly | H6: 40 | J6: NOS/month | K6: 2 | L6: 3 | M6: 4 | N6: 5 | O6: 6 | P6: Individual
C7: # Inspection | D7: Jumlah pelaksanaan kegiatan inspeksi untuk mendukung safety performance, sesuai tanggung jawab area dan berdasarkan list activity yang dibuat oleh masing-masing departemen. Calculation: # Jumlah inspeksi L1: 2 & <50% TBC L2: 3 & 60% TBC L3: 4 & 70% TBC L4: 5 & 80% TBC L5: 6 & 90% TBC | E7: Monthly | H7: 30 | J7: Index | K7: 1 | L7: 2 | M7: 3 | N7: 4 | O7: 5 | P7: Individual
C8: # Hazard Report | D8: Jumlah pelaksanaan kegiatan hazard report untuk mendukung safety performance. Calculation: # Jumlah Hazard Report L1: 1 & <50% TBC L2: 2 & 60% TBC L3: 3 & 70% TBC L4: 4 & 80% TBC L5: 5 & 90% TBC | E8: Monthly | H8: 15 | J8: Index | K8: 1 | L8: 2 | M8: 3 | N8: 4 | O8: 5 | P8: Individual
C9: Pengiriman Safety Site Weekly Report | D9: Pembuatan, Pengiriman evaluasi Mingguan dan efektifitas rekomendasi (Safety Performance, Evaluasi Hazard khususnya Hazard High Risk, Monitoring Pengawasan Area/Aktvitas Kritis, Evaluasi Pelaksanaan SIB, PJA Performance dan Tren Pelaporan Hazard High Risk, Observasi Area/Aktivitas Kritis, Evaluasi Hazard Covid serta rekomendasi hasil Evaluasi). L1: Hari Senin diatas pukul 17:00 dan <40% rekomendasi evaluator diimplementasikan L2: Hari Senin sebelum pukul 16:00 dan 40–54% rekomendasi evaluator diimplementasikan L3: Hari Senin sebelum Pukul 14:00 dan 55–64% rekomendasi evaluator diimplementasikan L4: Hari Senin sebelum Pukul 12:00 dan 65–74% rekomendasi evaluator diimplementasikan L5: Hari Senin sebelum Pukul 12:00 dan ≥75% rekomendasi evaluator diimplementasikan | E9: Monthly | F9: 8 | G9: 13 | I9: Constant | J9: Index | K9: 1 | L9: 2 | M9: 3 | N9: 4 | O9: 5 | P9: Individual
C10: Pengiriman Feed material untuk meeting alignment & ISC | D10: Pembuatan dan Pengiriman feed material meeting alignment & ISC setiap hari Jumat. L1: Hari Senin sebelum Pukul 12:00 dan Zero Thematic Issue L2: Hari Senin sebelum Pukul 10:00 dan Zero Thematic Issue L3: Hari Jumat sebelum Pukul 14:00 dan Zero Thematic Issue L4: Hari Jumat sebelum Pukul 12:00 dan Lead 1 Thematic Issue L5: Hari Jumat sebelum Pukul 10:00 dan Lead 2 Thematic Issue | E10: Monthly | F10: 5 | G10: 7 | I10: Constant | J10: Index | K10: 1 | L10: 2 | M10: 3 | N10: 4 | O10: 5
C11: Evaluasi Analisa Safety (Monthly Report) | D11: Laporan Safety Monthly site L1: Tanggal 9 L2: Tanggal 8 L3: Tanggal 7 L4: Tanggal 6 (Zero Program Scorecard Menurun dalam 2 periode kebelakang dari bulan Report Evaluasi secara repetitive) L5: Tanggal 5 (Zero Gap pada related causal Layer 2.4 dan 2.13) | E11: Monthly | F11: 8 | G11: 13 | I11: Constant | J11: Index | K11: 1 | L11: 2 | M11: 3 | N11: 4 | O11: 5 | P11: Individual
C12: Kontrol Pemenuhan Rekomendasi LPI | D12: Pemenuhan rekomendasi dari hasil investigasi (Berdasarkan list rekomendasi yang dikeluarkan dari tim OHS) L1: 90% dan terdapat RTP Check Incident Injury (First Aid up) dalam 2 tahun terakhir L2: 92% dan terdapat RTP Check Incident Injury (First Aid up) dalam 2 tahun terakhir L3: 94% dan terdapat RTP Check Incident Injury (First Aid up) dalam 2 tahun terakhir L4: 97% dan terdapat RTP Check Incident Injury (First Aid up) dalam 2 tahun terakhir L5: 99% dan terdapat RTP Check Incident Injury (First Aid up) dalam 2 tahun terakhir | E12: Half Yearly | F12: 8 | G12: 13 | I12: Constant | J12: Index | K12: =DCRS!K17 -> 1 | L12: =DCRS!L17 -> 2 | M12: =DCRS!M17 -> 3 | N12: =DCRS!N17 -> 4 | O12: =DCRS!O17 -> 5 | P12: Individual
C13: Monitoring Hazard Report & Inspeksi via BEATS | D13: =DCRS!D16 -> Monitoring yang dilakukan perihal jumlah laporan hazard & inspeksi dengan status closed dibandingkan dengan jumlah laporan hazard & inspeksi yang masuk setiap bulannya (All Site). L1: Closed 92% dan status Closed Overdue < 5% L2: Closed 94% dan status Closed Overdue < 4% L3: Closed 95% dan status Closed Overdue < 3% L4: Closed 97% dan status Closed Overdue < 2% L5: Closed 99% dan status Closed Overdue < 1% | E13: Monthly | F13: 5 | G13: 8 | I13: Constant | J13: % | K13: =DCRS!K16 -> 1 | L13: =DCRS!L16 -> 2 | M13: =DCRS!M16 -> 3 | N13: =DCRS!N16 -> 4 | O13: =DCRS!O16 -> 5 | P13: Support
B14: Innovation | C14: =DCRS!C18 -> Safety Evaluation Innovation Project Completion | D14: =DCRS!D18 -> Penyelesaian scope project dari project safety dashboard integration & automation secara on-time, atau pengerjaan unplanned project/tasks, project based L1: Completion : 80%, Improvement Generated : ≥1 improvement, Impact : Perbaikan minor pada reporting / dashboard L2: Completion : 85%, Improvement Generated : ≥2 improvement, Impact : Mempercepat proses monitoring atau reporting L3: Completion : 90%, Improvement Generated : ≥3 improvement, Impact : Mengurangi manual work / meningkatkan efisiensi proses L4: Completion : 100% dan Presented & Approved GM OHS, Improvement Generated : ≥4 improvement, Impact : Lintas fungsi (OHS / Operation) dan meningkatkan decision making L5: Completion : 100% dan Presented ke KTT, Improvement Generated : ≥5 improvement, Impact : Lintas Divisi Transformasi proses kerja / automation signifikan yang berdampak ke performance monitoring perusahaan | E14: Halfyearly | F14: 15 | G14: 18 | I14: Constant | J14: % | K14: =DCRS!K18 -> 1 | L14: =DCRS!L18 -> 2 | M14: =DCRS!M18 -> 3 | N14: =DCRS!N18 -> 4 | O14: =DCRS!O18 -> 5 | P14: Individual
B15: Total KPI | D15: =COUNTA(C2:C14) -> 13 | F15: =SUM(F2:F14) -> 70 | G15: =SUM(G2:G14) -> 100

Sheet DCRS
A1: Perspective | B1: Objective | C1: KPI | D1: Deskripsi | E1: Review Frequency | F1: Weightage Bobot | G1: Bobot 100% | H1: Detail Bobot | I1: UOM | J1: Calculation | K1: L1 | L1: L2 | M1: L3 | N1: L4 | O1: L5 | P1: DCRS
A2: Customer | B2: Identifikasi seluruh peraturan K3L terkait di organisasi | C2: % Identification and Evaluation of K3L Regulations based on Regulatory Compliance System | D2: S1 L1: <96% Pemenuhan GCI perusahaan L2: 97% Pemenuhan GCI perusahaan L3: 98% Pemenuhan GCI perusahaan L4: 99% Pemenuhan GCI perusahaan L5: 100% Pemenuhan GCI perusahaan based on Regulatory Compliance System S2 L1: 98% Pemenuhan GCI perusahaan L2: 99% Pemenuhan GCI perusahaan L3: 100% Pemenuhan GCI perusahaan L4: 100% Pemenuhan GCI perusahaan + Aditama GMP aspek Keselamatan L5: 100% Pemenuhan GCI perusahaan + Aditama GMP aspek Keselamatan dan trophy untuk salah satu aspek GMP di Berau Coal | E2: Halfyearly | F2: 3 | G2: 4 | I2: Index | J2: Constant | K2: 1 | L2: 2 | M2: 3 | N2: 4 | O2: 5 | P2: Support | T2: 3 | U2: 4
A3: Internal Business Process | B3: Strengthen OHS Management | C3: Ratio LTISR | D3: Index nilai penurunan LTISR berdasarkan range berdasarkan Permen 1827: target : L1: 6.000 ( Fatality) L2 : 84 hari (4 minor) L3: 63 hari (3 minor ) L4 : 42 hari (2 minor) L5 : 0 | E3: Quarterly | F3: 5 | G3: 7 | I3: Days | J3: Constant | K3: 6000 | L3: 84 | M3: 63 | N3: 42 | O3: 0 | P3: Support | T3: 5 | U3: 7
C4: Penurunan AFR | D4: Index nilai penurunan AFR dibandingkan performa aktual tahun sebelumnya target : L1: AFR avg/month dan kategori insiden lebih tinggi dari tahun sebelumnya L2 : AFR avg/month dan kategori insiden tidak ada perubahan dibanding tahun sebelumnya L3: AFR avg/month <5% dibanding AFR avg/month tahun sebelumnya L4 : AFR avg/month <7% dibanding AFR avg/month tahun sebelumnya L5 : AFR avg/month <7% dibanding AFR avg/month tahun sebelumnya dan kategori insiden tidak meningkat dibanding tahun 2024 | E4: Half Yearly | F4: 2.5 | G4: 3.5 | I4: Index | J4: Constant | K4: 1 | L4: 2 | M4: 3 | N4: 4 | O4: 5 | P4: Support | R4: Penambahan point AFR ke KPI req GM | T4: 2.5 | U4: 3.5
C5: Penurunan Jumlah incident HIPO dan Incident Berulang | D5: Frequency Incident kategori HIPO dan Insiden berulang menurun dibandingkan performa aktual tahun sebelumnya target : L1: HIPO Incident avg/month dan kategori insiden lebih tinggi dari tahun sebelumnya L2 : HIPO Incident avg/month dan kategori insiden tidak ada perubahan dibanding tahun sebelumnya L3: HIPO Incident avg/month <5% dibanding HIPO Incident avg/month tahun sebelumnya. L4 : HIPO Incident avg/month <7% dibanding HIPO Incident avg /month tahun sebelumnya, tidak terdapat pengulangan insiden (rootcause, lokasi dan aktivitas yang sama) selama tahun berjalan. L5 : HIPO Incident avg/month <7% dibanding HIPO Incident avg/month tahun sebelumnya, kategori insiden tidak meningkat dibanding tahun 2025 (jumlah HIPO GR), tidak terdapat pengulangan insiden (rootcause, lokasi dan aktivitas yang sama) di banding periode tahun sebelumnya dan selama tahun berjalan | E5: Half Yearly | F5: 2.5 | G5: 3.5 | I5: Index | J5: Constant | K5: 1 | L5: 2 | M5: 3 | N5: 4 | O5: 5 | P5: Support | R5: Request Penambahan Point KPI by GM OHS | T5: 2.5 | U5: 3.5
C6: # Coaching | D6: Jumlah pelaksanaan kegiatan coaching untuk mendukung safety performance. Calculation: # Jumlah coaching L1: 0 L2: 1 L3: 2 L4: 3 L5: 4 | E6: Monthly | F6: 6 | G6: 9 | H6: 15 | I6: Number/month | J6: Constant | K6: 0 | L6: 1 | M6: 2 | N6: 3 | O6: 4 | P6: Individual | T6: 6 | U6: 9
C7: # Observation | D7: Jumlah pelaksanaan kegiatan observasi untuk mendukung safety performance, sesuai tanggung jawab area dan berdasarkan list activity yang dibuat oleh masing-masing departemen. Calculation: # Jumlah observasi L1: 1 L2: 2 L3: 3 L4: 4 L5: 5 | E7: Monthly | H7: 40 | I7: Number/month | J7: Constant | K7: 1 | L7: 2 | M7: 3 | N7: 4 | O7: 5 | P7: Individual
C8: # Inspection | D8: Jumlah pelaksanaan kegiatan inspeksi untuk mendukung safety performance, sesuai tanggung jawab area dan berdasarkan list activity yang dibuat oleh masing-masing departemen. Calculation: # Jumlah inspeksi L1: 1 L2: 2 L3: 3 L4: 4 L5: 5 | E8: Monthly | H8: 30 | I8: Number/month | J8: Constant | K8: 1 | L8: 2 | M8: 3 | N8: 4 | O8: 5 | P8: Individual
C9: # Hazard Report | D9: Jumlah pelaksanaan kegiatan hazard report untuk mendukung safety performance. Calculation: # Jumlah Hazard Report L1: 0 L2: 1 L3: 2 L4: 3 L5: 4 | E9: Monthly | H9: 15 | I9: Number/month | J9: Constant | K9: 0 | L9: 1 | M9: 2 | N9: 3 | O9: 4 | P9: Individual
C10: ='Supt SEDCR'!D8 -> Laporan Rutin Bulanan ESDM | D10: ='Supt SEDCR'!E8 -> Tanggal pengumpulan laporan Bulanan ESDM L1: tanggal 12 L2: tanggal 11 L3: tanggal 10 L4: tanggal 9 L5: tanggal 8 | E10: Monthly | F10: 4 | G10: 6 | I10: Month Date | J10: Constant | K10: ='Supt SEDCR'!N8 -> 12 | L10: ='Supt SEDCR'!O8 -> 11 | M10: ='Supt SEDCR'!P8 -> 10 | N10: ='Supt SEDCR'!Q8 -> 9 | O10: ='Supt SEDCR'!R8 -> 8 | P10: Individual | T10: 4 | U10: 6
C11: Laporan RKAB ESDM | D11: ='Supt SEDCR'!E9 -> Tanggal pengumpulan laporan RKAB ESDM L1: tanggal 24 L2: tanggal 23 L3: tanggal 22 L4: tanggal 21 L5: tanggal 20 | E11: Quarterly | F11: 4 | G11: 6 | I11: Month Date | J11: Constant | K11: ='Supt SEDCR'!N9 -> 24 | L11: ='Supt SEDCR'!O9 -> 23 | M11: ='Supt SEDCR'!P9 -> 22 | N11: ='Supt SEDCR'!Q9 -> 21 | O11: ='Supt SEDCR'!R9 -> 20 | P11: Individual | T11: 4 | U11: 6
C12: Laporan P2K3 Triwulan | D12: ='Supt SEDCR'!E10 -> Tanggal pengumpulan laporan P2K3 Triwulan L1: tanggal 12 L2: tanggal 11 L3: tanggal 10 L4: tanggal 9 L5: tanggal 8 | E12: Quarterly | F12: 4 | G12: 6 | I12: Month Date | J12: Constant | K12: ='Supt SEDCR'!N10 -> 12 | L12: ='Supt SEDCR'!O10 -> 11 | M12: ='Supt SEDCR'!P10 -> 10 | N12: ='Supt SEDCR'!Q10 -> 9 | O12: ='Supt SEDCR'!R10 -> 8 | P12: Individual | T12: 4 | U12: 6
C13: Pengiriman weekly safety report (Safety alignment & ISC) | D13: Index ketepatan waktu pengiriman dan kualitas report weekly (untuk keperluan meeting safety alignment & ISC). L1: Dikirimkan setelah pukul 00:00 setiap hari Selasa dan <40% rekomendasi evaluator diimplementasikan L2: Dikirimkan di hari selasa sebelum pukul 23:59 dan 40–54% rekomendasi evaluator diimplementasikan L3: Dikirimkan setiap hari Senin sebelum pukul 22:00 dan 55–64% rekomendasi evaluator diimplementasikan L4: Dikirimkan setiap hari Senin sebelum pukul 21:00 dan 65–74% rekomendasi evaluator diimplementasikan L5: Dikirimkan setiap hari Senin sebelum pukul 21:00 dan ≥75% rekomendasi evaluator diimplementasikan | E13: Monthly | F13: 8 | G13: 11 | I13: Index | J13: Constant | K13: ='Supt SEDCR'!N15 -> 1 | L13: ='Supt SEDCR'!O15 -> 2 | M13: ='Supt SEDCR'!P15 -> 3 | N13: ='Supt SEDCR'!Q15 -> 4 | O13: ='Supt SEDCR'!R15 -> 5 | P13: Individual | T13: 8 | U13: 11
C14: Waktu Pengiriman Evaluasi Analisa Safety (monthly report) | D14: ='Supt SEDCR'!E16 -> Laporan Safety Performance disampaikan dalam forum HSECM, IT & Safety Alignment, serta ISC L1: Tanggal 9 L2: Tanggal 8 L3: Tanggal 7 L4: Tanggal 6 L5: Tanggal 5 | E14: Monthly | F14: 4 | G14: 6 | I14: Month Date | J14: Constant | K14: ='Supt SEDCR'!N16 -> 9 | L14: ='Supt SEDCR'!O16 -> 8 | M14: ='Supt SEDCR'!P16 -> 7 | N14: ='Supt SEDCR'!Q16 -> 6 | O14: ='Supt SEDCR'!R16 -> 5 | P14: Individual | T14: 4 | U14: 6
C15: Follow up temuan ESDM | D15: L5: 100% L4: 98% L3: 96% L2: 93% L1: 90% | E15: Halfyearly | F15: 4 | G15: 6 | I15: % | J15: Constant | K15: 0.9 | L15: 0.93 | M15: 0.96 | N15: 0.98 | O15: 1 | P15: Individual | T15: 4 | U15: 6
C16: Monitoring Hazard Report & Inspeksi via BEATS | D16: ='Supt SEDCR'!E7 -> Monitoring yang dilakukan perihal jumlah laporan hazard & inspeksi dengan status closed dibandingkan dengan jumlah laporan hazard & inspeksi yang masuk setiap bulannya (All Site). L1: Closed 92% dan status Closed Overdue < 5% L2: Closed 94% dan status Closed Overdue < 4% L3: Closed 95% dan status Closed Overdue < 3% L4: Closed 97% dan status Closed Overdue < 2% L5: Closed 99% dan status Closed Overdue < 1% | E16: Monthly | F16: 4 | G16: 6 | I16: Index | J16: Constant | K16: 1 | L16: 2 | M16: 3 | N16: 4 | O16: 5 | P16: Individual | T16: 4 | U16: 6
C17: % Fulfillment Incident investigation | D17: ='Supt SEDCR'!E17 -> Pemenuhan rekomendasi dari hasil investigasi (Berdasarkan list rekomendasi yang dikeluarkan dari tim OHS) L1: 90% dan terdapat RTP Check Incident Injury (First Aid up) dalam 2 tahun terakhir L2: 92% dan terdapat RTP Check Incident Injury (First Aid up) dalam 2 tahun terakhir L3: 94% dan terdapat RTP Check Incident Injury (First Aid up) dalam 2 tahun terakhir L4: 97% dan terdapat RTP Check Incident Injury (First Aid up) dalam 2 tahun terakhir L5: 99% dan terdapat RTP Check Incident Injury (First Aid up) dalam 2 tahun terakhir | E17: Halfyearly | F17: 4 | G17: 6 | I17: Index | J17: Constant | K17: ='Supt SEDCR'!N17 -> 1 | L17: ='Supt SEDCR'!O17 -> 2 | M17: ='Supt SEDCR'!P17 -> 3 | N17: ='Supt SEDCR'!Q17 -> 4 | O17: ='Supt SEDCR'!R17 -> 5 | P17: Individual | T17: 4 | U17: 6
B18: ='Supt SEDCR'!C18 -> Innovation | C18: ='Supt SEDCR'!D18 -> Safety Evaluation Innovation Project Completion | D18: ='Supt SEDCR'!E18 -> Penyelesaian scope project dari project safety dashboard integration & automation secara on-time, atau pengerjaan unplanned project/tasks, project based L1: Completion : 80%, Improvement Generated : ≥1 improvement, Impact : Perbaikan minor pada reporting / dashboard L2: Completion : 85%, Improvement Generated : ≥2 improvement, Impact : Mempercepat proses monitoring atau reporting L3: Completion : 90%, Improvement Generated : ≥3 improvement, Impact : Mengurangi manual work / meningkatkan efisiensi proses L4: Completion : 100% dan Presented & Approved GM OHS, Improvement Generated : ≥4 improvement, Impact : Lintas fungsi (OHS / Operation) dan meningkatkan decision making L5: Completion : 100% dan Presented ke KTT, Improvement Generated : ≥5 improvement, Impact : Lintas Divisi Transformasi proses kerja / automation signifikan yang berdampak ke performance monitoring perusahaan | E18: Halfyearly | F18: 15 | G18: 20 | H18: 30 | I18: Index | J18: Constant | K18: ='Supt SEDCR'!N18 -> 1 | L18: ='Supt SEDCR'!O18 -> 2 | M18: ='Supt SEDCR'!P18 -> 3 | N18: ='Supt SEDCR'!Q18 -> 4 | O18: ='Supt SEDCR'!R18 -> 5 | P18: Individual | T18: 15 | U18: 20
B19: Total KPI | D19: =COUNTA(C2:C18) -> 17 | F19: =SUM(F2:F18) -> 70 | G19: =SUM(G2:G18) -> 100

Sheet IFA
A1: # Coaching | B1: Jumlah pelaksanaan kegiatan coaching untuk mendukung safety performance. Calculation: # Jumlah coaching L1: 0 L2: 1 L3: 2 L4: 3 L5: 4 | C1: Monthly | D1: 6 | E1: 9 | F1: 15 | G1: Number/month | H1: Constant | I1: 0 | J1: 1 | K1: 2 | L1: 3 | M1: 4 | P1: 4
A2: # Observation | B2: Jumlah pelaksanaan kegiatan observasi untuk mendukung safety performance, sesuai tanggung jawab area dan berdasarkan list activity yang dibuat oleh masing-masing departemen. Calculation: # Jumlah observasi L1: 1 L2: 2 L3: 3 L4: 4 L5: 5 | C2: Monthly | F2: 40 | G2: Number/month | H2: Constant | I2: 1 | J2: 2 | K2: 3 | L2: 4 | M2: 5
A3: # Inspection | B3: Jumlah pelaksanaan kegiatan inspeksi untuk mendukung safety performance, sesuai tanggung jawab area dan berdasarkan list activity yang dibuat oleh masing-masing departemen. Calculation: # Jumlah inspeksi L1: 1 L2: 2 L3: 3 L4: 4 L5: 5 | C3: Monthly | F3: 30 | G3: Number/month | H3: Constant | I3: 1 | J3: 2 | K3: 3 | L3: 4 | M3: 5
A4: # Hazard Report | B4: Jumlah pelaksanaan kegiatan hazard report untuk mendukung safety performance. Calculation: # Jumlah Hazard Report L1: 0 L2: 1 L3: 2 L4: 3 L5: 4 | C4: Monthly | F4: 15 | G4: Number/month | H4: Constant | I4: 0 | J4: 1 | K4: 2 | L4: 3 | M4: 4
A5: Safety Evaluation Innovation Project Completion | B5: Penyelesaian scope project dari project safety dashboard integration & automation secara on-time, atau pengerjaan unplanned project/tasks, project based L1: Completion : 80%, Improvement Generated : ≥1 improvement, Impact : Perbaikan minor pada reporting / dashboard L2: Completion : 85%, Improvement Generated : ≥2 improvement, Impact : Mempercepat proses monitoring atau reporting L3: Completion : 90%, Improvement Generated : ≥3 improvement, Impact : Mengurangi manual work / meningkatkan efisiensi proses L4: Completion : 100% dan Presented & Approved GM OHS, Improvement Generated : ≥4 improvement, Impact : Lintas fungsi (OHS / Operation) dan meningkatkan decision making L5: Completion : 100% dan Presented ke KTT, Improvement Generated : ≥5 improvement, Impact : Lintas Divisi Transformasi proses kerja / automation signifikan yang berdampak ke performance monitoring perusahaan | C5: Halfyearly | D5: 15 | E5: 20 | F5: 30 | G5: Index | H5: Constant | I5: 1 | J5: 2 | K5: 3 | L5: 4 | M5: 5 | P5: 10
A6: Monitoring Hazard Report & Inspeksi via BEATS | B6: Monitoring yang dilakukan perihal jumlah laporan hazard & inspeksi dengan status closed dibandingkan dengan jumlah laporan hazard & inspeksi yang masuk setiap bulannya (All Site). L1: Closed 92% dan status Closed Overdue < 5% L2: Closed 94% dan status Closed Overdue < 4% L3: Closed 95% dan status Closed Overdue < 3% L4: Closed 97% dan status Closed Overdue < 2% L5: Closed 99% dan status Closed Overdue < 1% | C6: Monthly | D6: 4 | E6: 6 | G6: Index | H6: Constant | I6: 1 | J6: 2 | K6: 3 | L6: 4 | M6: 5 | P6: 3
A7: % Fulfillment Incident investigation | B7: Pemenuhan rekomendasi dari hasil investigasi (Berdasarkan list rekomendasi yang dikeluarkan dari tim OHS) L1: 90% dan terdapat RTP Check Incident Injury (First Aid up) dalam 2 tahun terakhir L2: 92% dan terdapat RTP Check Incident Injury (First Aid up) dalam 2 tahun terakhir L3: 94% dan terdapat RTP Check Incident Injury (First Aid up) dalam 2 tahun terakhir L4: 97% dan terdapat RTP Check Incident Injury (First Aid up) dalam 2 tahun terakhir L5: 99% dan terdapat RTP Check Incident Injury (First Aid up) dalam 2 tahun terakhir | C7: Halfyearly | D7: 4 | E7: 6 | G7: Index | H7: Constant | I7: 1 | J7: 2 | K7: 3 | L7: 4 | M7: 5 | P7: 3
E8: 0.41 | P8: =SUM(P1:P7) -> 20

Sheet Supt Marine Fix
A1: Perspective | B1: Objective | C1: Grup KPI | D1: Nama KPI | E1: Deskripsi | F1: Weightage Bobot | G1: Bobot 100% | H1: Detail Bobot | I1: Review Frequency | J1: Calculation | K1: UOM | L1: L1 | M1: L2 | N1: L3 | O1: L4 | P1: L5 | Q1: Marine Safety Supt Heru
A2: Customer | B2: Identifikasi seluruh peraturan K3L terkait di organisasi | D2: % Identification and Evaluation of K3L Regulations based on Regulatory Compliance System | E2: S1 L1: <96% Pemenuhan GCI perusahaan L2: 97% Pemenuhan GCI perusahaan L3: 98% Pemenuhan GCI perusahaan L4: 99% Pemenuhan GCI perusahaan L5: 100% Pemenuhan GCI perusahaan based on Regulatory Compliance System S2 L1: 98% Pemenuhan GCI perusahaan L2: 99% Pemenuhan GCI perusahaan L3: 100% Pemenuhan GCI perusahaan L4: 100% Pemenuhan GCI perusahaan + Aditama GMP aspek Keselamatan L5: 100% Pemenuhan GCI perusahaan + Aditama GMP aspek Keselamatan dan trophy untuk salah satu aspek GMP di Berau Coal | F2: 5 | G2: 7 | I2: Halyearly | J2: Constant | K2: Index | L2: 1 | M2: 2 | N2: 3 | O2: 4 | P2: 5 | Q2: Support | S2: 5 | T2: 7
A3: Internal Business Process | B3: Strengthen OHS Management | D3: Penurunan Jumlah incident HIPO dan Incident Berulang | E3: Frequency Incident kategori HIPO dan Insiden berulang menurun dibandingkan performa aktual tahun sebelumnya (Marine) target : L1: HIPO Incident avg/month dan kategori insiden lebih tinggi dari tahun sebelumnya L2 : HIPO Incident avg/month dan kategori insiden tidak ada perubahan dibanding tahun sebelumnya L3: HIPO Incident avg/month <5% dibanding HIPO Incident avg/month tahun sebelumnya. L4 : HIPO Incident avg/month <7% dibanding HIPO Incident avg /month tahun sebelumnya, tidak terdapat pengulangan insiden (rootcause, lokasi dan aktivitas yang sama) selama tahun berjalan. L5 : HIPO Incident avg/month <7% dibanding HIPO Incident avg/month tahun sebelumnya, kategori insiden tidak meningkat dibanding tahun 2025 (jumlah HIPO GR), tidak terdapat pengulangan insiden (rootcause, lokasi dan aktivitas yang sama) di banding periode tahun sebelumnya dan selama tahun berjalan | F3: 6 | G3: 9 | I3: Half Yearly | J3: Constant | K3: Index | L3: 1 | M3: 2 | N3: 3 | O3: 4 | P3: 5 | Q3: Support | S3: 6 | T3: 9
